Workbook

Sheet Dashboard
A1: DASHBOARD — PROPRIEDADE INTELECTUAL | IFMA
A2: Atualizado em: 04/04/2026 | Fonte: INPI / NIT-IFMA
A3: Total de PIs | E3: Patentes | I3: Softwares | M3: Concedidas/Cert.
A5: =COUNTA(Dados!B3:B5000) -> 191 | E5: =COUNTIF(Dados!B:B,"Patente de Invenção")+COUNTIF(Dados!B:B,"Modelo de Utilidade") -> 64 | I5: =COUNTIF(Dados!B:B,"Software") -> 87 | M5: =COUNTIF(Dados!H:H,"Concedida")+COUNTIF(Dados!H:H,"Certificado Emitido") -> 88

Sheet Indicadores
A1: Total por Tipo de PI | D1: Por Status | G1: Depósitos por Ano | J1: Ranking por Campus
A2: Patente de Invenção | B2: =COUNTIF(Dados!B:B,"Patente de Invenção") -> 48 | D2: Certificado Emitido | E2: =COUNTIF(Dados!H:H,"Certificado Emitido") -> 79 | G2: 2009 | H2: =SUMPRODUCT((ISNUMBER(SEARCH("2009",Dados!G:G)))*1) -> 2 | J2: Monte Castelo | K2: =COUNTIF(Dados!D:D,"Monte Castelo") -> 49
A3: Modelo de Utilidade | B3: =COUNTIF(Dados!B:B,"Modelo de Utilidade") -> 16 | D3: Concedida | E3: =COUNTIF(Dados!H:H,"Concedida") -> 9 | G3: 2010 | H3: =SUMPRODUCT((ISNUMBER(SEARCH("2010",Dados!G:G)))*1) -> 0 | J3: Imperatriz | K3: =COUNTIF(Dados!D:D,"Imperatriz") -> 25
A4: Software | B4: =COUNTIF(Dados!B:B,"Software") -> 87 | D4: Deferida | E4: =COUNTIF(Dados!H:H,"Deferida") -> 1 | G4: 2011 | H4: =SUMPRODUCT((ISNUMBER(SEARCH("2011",Dados!G:G)))*1) -> 0 | J4: Reitoria | K4: =COUNTIF(Dados!D:D,"Reitoria") -> 19
A5: Marca | B5: =COUNTIF(Dados!B:B,"Marca") -> 34 | D5: Em andamento | E5: =COUNTIF(Dados!H:H,"Em andamento") -> 39 | G5: 2012 | H5: =SUMPRODUCT((ISNUMBER(SEARCH("2012",Dados!G:G)))*1) -> 2 | J5: Caxias | K5: =COUNTIF(Dados!D:D,"Caxias") -> 11
A6: Desenho Industrial | B6: =COUNTIF(Dados!B:B,"Desenho Industrial") -> 6 | D6: Em exame | E6: =COUNTIF(Dados!H:H,"Em exame") -> 0 | G6: 2013 | H6: =SUMPRODUCT((ISNUMBER(SEARCH("2013",Dados!G:G)))*1) -> 0 | J6: Araioses | K6: =COUNTIF(Dados!D:D,"Araioses") -> 11
A7: TOTAL | B7: =SUM(B2:B6) -> 191 | D7: Depositado | E7: =COUNTIF(Dados!H:H,"Depositado") -> 35 | G7: 2014 | H7: =SUMPRODUCT((ISNUMBER(SEARCH("2014",Dados!G:G)))*1) -> 1 | J7: Açailândia | K7: =COUNTIF(Dados!D:D,"Açailândia") -> 13
D8: Aguardando Certificado | E8: =COUNTIF(Dados!H:H,"Aguardando Certificado") -> 1 | G8: 2015 | H8: =SUMPRODUCT((ISNUMBER(SEARCH("2015",Dados!G:G)))*1) -> 7 | J8: Timon | K8: =COUNTIF(Dados!D:D,"Timon") -> 5
D9: Indeferida | E9: =COUNTIF(Dados!H:H,"Indeferida") -> 9 | G9: 2016 | H9: =SUMPRODUCT((ISNUMBER(SEARCH("2016",Dados!G:G)))*1) -> 0 | J9: Grajaú | K9: =COUNTIF(Dados!D:D,"Grajaú") -> 3
D10: Arquivada | E10: =COUNTIF(Dados!H:H,"Arquivada") -> 11 | G10: 2017 | H10: =SUMPRODUCT((ISNUMBER(SEARCH("2017",Dados!G:G)))*1) -> 1 | J10: Maracanã | K10: =COUNTIF(Dados!D:D,"Maracanã") -> 2
D11: Anulado | E11: =COUNTIF(Dados!H:H,"Anulado") -> 5 | G11: 2018 | H11: =SUMPRODUCT((ISNUMBER(SEARCH("2018",Dados!G:G)))*1) -> 6 | J11: Codó | K11: =COUNTIF(Dados!D:D,"Codó") -> 8
D12: Em sigilo | E12: =COUNTIF(Dados!H:H,"Em sigilo") -> 2 | G12: 2019 | H12: =SUMPRODUCT((ISNUMBER(SEARCH("2019",Dados!G:G)))*1) -> 9 | J12: São José de Ribamar | K12: =COUNTIF(Dados!D:D,"São José de Ribamar") -> 2
G13: 2020 | H13: =SUMPRODUCT((ISNUMBER(SEARCH("2020",Dados!G:G)))*1) -> 18 | J13: São João dos Patos | K13: =COUNTIF(Dados!D:D,"São João dos Patos") -> 1
G14: 2021 | H14: =SUMPRODUCT((ISNUMBER(SEARCH("2021",Dados!G:G)))*1) -> 14 | J14: Centro Histórico | K14: =COUNTIF(Dados!D:D,"Centro Histórico") -> 2
G15: 2022 | H15: =SUMPRODUCT((ISNUMBER(SEARCH("2022",Dados!G:G)))*1) -> 14 | J15: Alcântara | K15: =COUNTIF(Dados!D:D,"Alcântara") -> 0
G16: 2023 | H16: =SUMPRODUCT((ISNUMBER(SEARCH("2023",Dados!G:G)))*1) -> 13 | J16: Barra do Corda | K16: =COUNTIF(Dados!D:D,"Barra do Corda") -> 0
G17: 2024 | H17: =SUMPRODUCT((ISNUMBER(SEARCH("2024",Dados!G:G)))*1) -> 42 | J17: Cotitular | K17: =COUNTIF(Dados!D:D,"Cotitular") -> 1
G18: 2025 | H18: =SUMPRODUCT((ISNUMBER(SEARCH("2025",Dados!G:G)))*1) -> 46 | J18: Não informado | K18: =COUNTIF(Dados!D:D,"Não informado") -> 32
G19: 2026 | H19: =SUMPRODUCT((ISNUMBER(SEARCH("2026",Dados!G:G)))*1) -> 11

Sheet Dados
A1: IFMA — REGISTRO DE PROPRIEDADE INTELECTUAL
A2: # | B2: Tipo | C2: Título | D2: Campus | E2: Autor(es) | F2: Nº do Processo | G2: Data de Depósito | H2: Status | I2: Data do Status | J2: Observações
A3: 1 | B3: Desenho Industrial | C3: PADRÃO ORNAMENTAL APLICADO A/EM JOGO DE CARTAS | D3: Açailândia | E3: DAILSON COELHO ABREU | F3: BR 30 2024 001621 2 | G3: 04/04/2024 | H3: Indeferida
A4: 2 | B4: Desenho Industrial | C4: ESTOJOS DE BARALHO | D4: Açailândia | E4: DAILSON COELHO ABREU | F4: BR 32 2025 000148 2 | G4: 14/01/2025 | H4: Indeferida
A5: 3 | B5: Desenho Industrial | C5: PEÇAS DE TABULEIRO | D5: Açailândia | E5: RAIFRAN ABIDIMAR DE CASTRO | F5: BR 30 2025 008736 8 | G5: 18/12/2025 | H5: Depositado
A6: 4 | B6: Desenho Industrial | C6: FICHAS PARA JOGOS | D6: Açailândia | E6: DAILSON COELHO ABREU | F6: BR 30 2025 007116 0 | G6: 21/10/2025 | H6: Depositado
A7: 5 | B7: Desenho Industrial | C7: SUPORTES PARA CARTAS [PARA JOGOS DE CARTAS] | D7: Açailândia | E7: DAILSON COELHO ABREU | F7: BR 30 2025 007118 6 | G7: 21/10/2025 | H7: Depositado
A8: 6 | B8: Desenho Industrial | C8: PADRÃO ORNAMENTAL APLICADO A/FOTOGRAFIA | D8: Monte Castelo | E8: IVANA MÁRCIA OLIVEIRA MAIA | F8: BR 30 2024 001932 7 | G8: 23/04/2024 | H8: Concedida
A9: 7 | B9: Marca | C9: PoliTeCs Políticas Públicas, Tecnologias Sociais e Ações Mitigadoras para Sociedade do século XXI | D9: Açailândia | E9: RAIFRAN ABIDIMAR | F9: 937675342 | G9: 16/01/2025 | H9: Depositado
A10: 8 | B10: Marca | C10: CidBeeS Gestão Democrático-Participativa de Cidades e Sustentabilidade Socioambiental | D10: Açailândia | E10: RAIFRAN ABIDIMAR | F10: 937676101 | G10: 16/01/2025 | H10: Depositado
A11: 9 | B11: Marca | C11: SiiGiT- NCL 28 | D11: Açailândia | E11: RAIFRAN ABIDIMAR | F11: 937675024 | G11: 16/01/2025 | H11: Depositado
A12: 10 | B12: Marca | C12: SiiGiT- NCL 41 | D12: Açailândia | E12: RAIFRAN ABIDIMAR | F12: 937674702 | G12: 16/01/2025 | H12: Depositado
A13: 11 | B13: Marca | C13: Deck Parasite | D13: Açailândia | E13: DAILSON COELHO ABREU | F13: 933640714 | G13: 26/02/2024 | H13: Deferida | J13: Protocolado cumprimento de exigência em 19/11/2025
A14: 12 | B14: Marca | C14: DanTUS Degradação Ambiental, Territorialização e Sustentabilidade | D14: Açailândia | E14: IFMA | F14: 934427151 | G14: 30/04/2024 | H14: Concedida | J14: Concessão de Registro. Renovar registro em 2035.
A15: 13 | B15: Marca | C15: InterPoIS Geopolítica, Desenvolvimento Socioeconômico e Sustentabilidade | D15: Açailândia | E15: IFMA | F15: 934426970 | G15: 30/04/2024 | H15: Depositado | J15: exame de mérito
A16: 14 | B16: Marca | C16: MERMÃS DIGITAIS | D16: IMPERATRIZ | E16: SIMONE AZEVEDO/ LAILLA GALENO | F16: 933678290 | G16: 28/02/2024 | H16: Concedida | J16: exame de mérito
A17: 15 | B17: Marca | C17: TEIA DESIGN LAB - NCL 9 | D17: Monte Castelo | E17: CAMILA ANDRADE DOS SANTOS | F17: 940468603 | G17: 06/08/2025 | H17: Depositado | J17: Protocolada
A18: 16 | B18: Marca | C18: TEIA DESIGN LAB - NCL 41 | D18: Monte Castelo | E18: CAMILA ANDRADE DOS SANTOS | F18: 940469138 | G18: 06/08/2025 | H18: Depositado | J18: Protocolada
A19: 17 | B19: Marca | C19: TEIA DESIGN LAB - NCL 42 | D19: Monte Castelo | E19: CAMILA ANDRADE DOS SANTOS | F19: 940468980 | G19: 06/08/2025 | H19: Depositado | J19: Protocolada
A20: 18 | B20: Marca | C20: buddy robotics | D20: Monte Castelo | E20: MARCELO EUGENIO | F20: 938447343 | G20: 21/03/2025 | H20: Depositado
A21: 19 | B21: Marca | C21: PPGCA Programa de Pós-Graduação em Computação Aplicada | D21: Monte Castelo | E21: OMAR ANDRES CARMONA CORTES | F21: 938448226 | G21: 21/03/2025 | H21: Depositado
A22: 20 | B22: Marca | C22: LABENSAIOS-Laboratório de Ensaios Mecânicos e Termomecânicos | D22: Monte Castelo | E22: SAMUEL FILGUEIRAS RODRIGUES | F22: 938486594 | G22: 25/03/2025 | H22: Depositado
A23: 21 | B23: Marca | C23: AÇAÍMOV | D23: Não informado | E23: BREHME D NAPOLI REIS DE MESQUITA | F23: 935644822 | G23: 01/08/2024 | H23: Depositado | J23: exame de mérito
A24: 22 | B24: Marca | C24: Fabrica de Inovação | D24: Reitoria | E24: IFMA | F24: 930353870 | G24: 08/05/2023 | H24: Concedida | J24: Concessão de Registro. Renovar regsitro em 2034.
A25: 23 | B25: Marca | C25: Editora IFMA | D25: Reitoria | E25: IFMA | F25: 930353862 | G25: 08/05/2023 | H25: Concedida | J25: Concessão de Registro. Renovar regsitro em 2033.
A26: 24 | B26: Marca | C26: [re]design | D26: Reitoria | E26: IFMA | F26: 942372620 | G26: 09/01/2026 | H26: Depositado | J26: Protocolada
A27: 25 | B27: Marca | C27: Innovation factory | D27: Reitoria | E27: IFMA | F27: 936573295 | G27: 10/10/2024 | H27: Depositado | J27: protocolada
A28: 26 | B28: Marca | C28: Innovation factory | D28: Reitoria | E28: IFMA | F28: 936572736 | G28: 10/10/2024 | H28: Depositado | J28: protocolada
A29: 27 | B29: Marca | C29: NÚCLEO DE DESIGN E TECNOLOGIAS DA INFORMAÇÃO E COMUNICAÇÃO | D29: Reitoria | E29: IFMA | F29: 942995031 | G29: 11/03/2026 | H29: Depositado | J29: Protocolada
A30: 28 | B30: Marca | C30: Astronomia no Sertão | D30: Reitoria | E30: IFMA | F30: 930393848 | G30: 11/05/2023 | H30: Concedida | J30: Registro deferido. Aguardando pagamento da taxa de concessão do registro.
A31: 29 | B31: Marca | C31: SETE PERGUNTAS PODCAST | D31: Reitoria | E31: IFMA | F31: 937659738 | G31: 15/01/2025 | H31: Depositado | J31: Publicado para apresentação de oposição
A32: 30 | B32: Marca | C32: IFMA AFIRMATIVO | D32: Reitoria | E32: IFMA | F32: 942276795 | G32: 23/12/2025 | H32: Depositado | J32: Protocolada
A33: 31 | B33: Marca | C33: IFMA LIVRE DE VIOLÊNCIA DE GÊNERO | D33: Reitoria | E33: IFMA | F33: 942241649 | G33: 23/12/2025 | H33: Depositado | J33: Protocolada
A34: 32 | B34: Marca | C34: IFMA NO MUNDO | D34: Reitoria | E34: IFMA | F34: 942276949 | G34: 23/12/2025 | H34: Depositado | J34: Protocolada
... A40: 38 | B40: Marca | C40: Processo Eletrônico Projeto Estratégico | D40: Reitoria | E40: IFMA | F40: 942277422 | G40: 23/12/2025 | H40: Depositado | J40: Protocolada
A41: 39 | B41: Marca | C41: Mara BIOTECH | D41: São José de Ribamar | E41: FABIA HOLANDA DE BRITO | F41: 939116278 | G41: 13/05/2025 | H41: Depositado
A42: 40 | B42: Marca | C42: IFMA CAST - NCL38 | D42: Timon | E42: NARA SUELLEN LEONCIO CHAVES | F42: 940468433 | G42: 06/08/2025 | H42: Depositado | J42: Protocolada
A43: 41 | B43: Modelo de Utilidade | C43: DISPOSITIVO DE PROTEÇÃO E HIGIENIZAÇÃO/DESINFECÇÃO PARA ESPONJAS DE COZINHA | D43: Araioses | E43: LUIS MESQUITA DE SOUSA FILHO | F43: BR 10 2020 005111 3 | G43: 13/03/2020 | H43: Em andamento | J43: O pedido foi notificado pelo INPI na RPI nº 2827, de 11/03/25, onde foi apontado falta de novidade / atividade inventiva, apresentando anterioridades muito similares. Após reunião com os inventores, no dia 24/03/25, ficou claro que não haveria possib
A44: 42 | B44: Modelo de Utilidade | C44: PRENSA TÉRMICA PARA PLASTIFICAÇÃO E MISTURA COMPACTA DE MATERIAL POLIMÉRICO | D44: Codó | E44: BRUNO LEONARDY SOUSA LOPES | F44: BR 20 2022 000265 2 | G44: 07/01/2022 | H44: Em andamento
A45: 43 | B45: Modelo de Utilidade | C45: CAIXA MODULAR RÍGIDA DE CRIAÇÃO RACIONAL DE ABELHAS SEM FERRÃO | D45: GRA | E45: LUIZ OTÁVIO DE OLIVEIRA SOUZA JUNIOR | F45: BR 10 2026 005212 4 | G45: 05/03/2026 | H45: Em andamento
...
